try {
  throw ValueError
} catch e : ValueError {
  print('c')
}